<mujoco model="step6">
  <include file="./common/skybox.xml"/>
  <include file="./common/visual.xml"/>
  <include file="./common/materials.xml"/>


  <compiler angle="radian" meshdir="/home/va/om/step/sim/pyjoco/6_dof_ktech" autolimits="true"/>


  <statistic meansize="0.05"/>
  <default>
    <default class="step6">
      <joint damping="1" armature="0.1"/>
      <default class="visual">
        <geom type="mesh" contype="0" conaffinity="0" group="2" material="black"/>
      </default>
      <default class="collision">
        <geom group="3" mass="0" density="0" />
      </default>
    </default>
  </default>
  <asset>
    <material name="black" rgba="0.1 0.1 0.1 1"/>
    <material name="white" rgba="1 1 1 1"/>
    <mesh scale="0.001 0.001 0.001" file="pelvis.stl"/>
    <mesh scale="0.001 0.001 0.001" file="step_bot_left_ankle_link.stl"/>
    <mesh scale="0.001 0.001 0.001" file="step_bot_left_knee_pitch_link.stl"/>
    <mesh scale="0.001 0.001 0.001" file="step_bot_left_hip_roll_link.stl"/>
    <mesh scale="0.001 0.001 0.001" file="step_bot_left_shin_link.stl"/>
    <mesh scale="0.001 0.001 0.001" file="step_bot_right_ankle_link.stl"/>
    <mesh scale="0.001 0.001 0.001" file="step_bot_right_knee_pitch_link.stl"/>
    <mesh scale="0.001 0.001 0.001" file="step_bot_right_hip_roll_link.stl"/>
    <mesh scale="0.001 0.001 0.001" file="step_bot_right_shin_link.stl"/>

  </asset>
  <worldbody>
    <light mode="targetbodycom" target="base" pos="2 0 2.5"/>
    <body name="base" pos="0 0 0.66" childclass="step6" >
      <freejoint/>
      <geom type="mesh"  mesh="pelvis" class="collision" mass="5.39"/>
      <geom class="visual" mesh="pelvis"/>
      <body>
        <body>
        <joint name="left_hip_roll" pos="-0.09 0 0 " axis="0 1 0" range="-0.43 0.43"/>
        <geom  pos="-0.09 0 0.0" type="mesh"  mesh="step_bot_left_hip_roll_link" class="collision" />
        <geom  pos="-0.09 0 0.0" class="visual" mesh="step_bot_left_hip_roll_link"   />
        </body>
        <body>
        <joint name="right_hip_roll" pos="0.09 0 0 " axis="0 1 0" range="-0.43 0.43"/>
        <geom  pos="-0.065 0.1 -0.15" type="mesh"  mesh="step_bot_right_hip_roll_link" class="collision"  />
        <geom  pos="-0.065 0.1 -0.15" class="visual" mesh="step_bot_right_hip_roll_link"/>
        </body>
      </body>
    </body>

  </worldbody>
  <actuator>
    <position name="left_hip_roll" joint="left_hip_roll" ctrlrange="-10 10"  kp="50"/>
    <position name="right_hip_roll" joint="right_hip_roll" ctrlrange="-10 10"  kp="50"/>
  </actuator>

</mujoco>